# GPT-Academic Report
## 翻译 private_upload\default_user\2024-05-16-20-50-37\README.md.part-0.md

[Local Message] 警告，线程0在执行过程中遭遇问题, Traceback：

```
Traceback (most recent call last):
  File ".\crazy_functions\crazy_utils.py", line 228, in _req_gpt
    gpt_say = predict_no_ui_long_connection(
  File ".\request_llms\bridge_all.py", line 826, in predict_no_ui_long_connection
    return method(inputs, llm_kwargs, history, sys_prompt, observe_window, console_slience)
  File ".\request_llms\bridge_chatgpt.py", line 120, in predict_no_ui_long_connection
    raise RuntimeError("OpenAI拒绝了请求：" + error_msg)
RuntimeError: OpenAI拒绝了请求：{    "error": {        "message": "Incorrect API key provided: sk-SGPQq***************************************DXDl. You can find your API key at https://platform.openai.com/account/api-keys.",        "type": "invalid_request_error",        "param": null,        "code": "invalid_api_key"    }}
```

[Local Message] 警告，线程0在执行过程中遭遇问题, Traceback：

```
Traceback (most recent call last):
  File ".\crazy_functions\crazy_utils.py", line 228, in _req_gpt
    gpt_say = predict_no_ui_long_connection(
  File ".\request_llms\bridge_all.py", line 826, in predict_no_ui_long_connection
    return method(inputs, llm_kwargs, history, sys_prompt, observe_window, console_slience)
  File ".\request_llms\bridge_chatgpt.py", line 120, in predict_no_ui_long_connection
    raise RuntimeError("OpenAI拒绝了请求：" + error_msg)
RuntimeError: OpenAI拒绝了请求：{    "error": {        "message": "Incorrect API key provided: sk-SGPQq***************************************DXDl. You can find your API key at https://platform.openai.com/account/api-keys.",        "type": "invalid_request_error",        "param": null,        "code": "invalid_api_key"    }}
```

[Local Message] 警告，线程0在执行过程中遭遇问题, Traceback：

```
Traceback (most recent call last):
  File ".\crazy_functions\crazy_utils.py", line 228, in _req_gpt
    gpt_say = predict_no_ui_long_connection(
  File ".\request_llms\bridge_all.py", line 826, in predict_no_ui_long_connection
    return method(inputs, llm_kwargs, history, sys_prompt, observe_window, console_slience)
  File ".\request_llms\bridge_chatgpt.py", line 120, in predict_no_ui_long_connection
    raise RuntimeError("OpenAI拒绝了请求：" + error_msg)
RuntimeError: OpenAI拒绝了请求：{    "error": {        "message": "Incorrect API key provided: sk-SGPQq***************************************DXDl. You can find your API key at https://platform.openai.com/account/api-keys.",        "type": "invalid_request_error",        "param": null,        "code": "invalid_api_key"    }}
```



## 翻译 private_upload\default_user\2024-05-16-20-50-37\README.md.part-1.md

[Local Message] 警告，线程1在执行过程中遭遇问题, Traceback：

```
Traceback (most recent call last):
  File ".\crazy_functions\crazy_utils.py", line 228, in _req_gpt
    gpt_say = predict_no_ui_long_connection(
  File ".\request_llms\bridge_all.py", line 826, in predict_no_ui_long_connection
    return method(inputs, llm_kwargs, history, sys_prompt, observe_window, console_slience)
  File ".\request_llms\bridge_chatgpt.py", line 120, in predict_no_ui_long_connection
    raise RuntimeError("OpenAI拒绝了请求：" + error_msg)
RuntimeError: OpenAI拒绝了请求：{    "error": {        "message": "Incorrect API key provided: sk-SGPQq***************************************DXDl. You can find your API key at https://platform.openai.com/account/api-keys.",        "type": "invalid_request_error",        "param": null,        "code": "invalid_api_key"    }}
```

[Local Message] 警告，线程1在执行过程中遭遇问题, Traceback：

```
Traceback (most recent call last):
  File ".\crazy_functions\crazy_utils.py", line 228, in _req_gpt
    gpt_say = predict_no_ui_long_connection(
  File ".\request_llms\bridge_all.py", line 826, in predict_no_ui_long_connection
    return method(inputs, llm_kwargs, history, sys_prompt, observe_window, console_slience)
  File ".\request_llms\bridge_chatgpt.py", line 120, in predict_no_ui_long_connection
    raise RuntimeError("OpenAI拒绝了请求：" + error_msg)
RuntimeError: OpenAI拒绝了请求：{    "error": {        "message": "Incorrect API key provided: sk-SGPQq***************************************DXDl. You can find your API key at https://platform.openai.com/account/api-keys.",        "type": "invalid_request_error",        "param": null,        "code": "invalid_api_key"    }}
```

[Local Message] 警告，线程1在执行过程中遭遇问题, Traceback：

```
Traceback (most recent call last):
  File ".\crazy_functions\crazy_utils.py", line 228, in _req_gpt
    gpt_say = predict_no_ui_long_connection(
  File ".\request_llms\bridge_all.py", line 826, in predict_no_ui_long_connection
    return method(inputs, llm_kwargs, history, sys_prompt, observe_window, console_slience)
  File ".\request_llms\bridge_chatgpt.py", line 120, in predict_no_ui_long_connection
    raise RuntimeError("OpenAI拒绝了请求：" + error_msg)
RuntimeError: OpenAI拒绝了请求：{    "error": {        "message": "Incorrect API key provided: sk-SGPQq***************************************DXDl. You can find your API key at https://platform.openai.com/account/api-keys.",        "type": "invalid_request_error",        "param": null,        "code": "invalid_api_key"    }}
```



